INFO     root:conftest.py:20 Test session started.
WARNING  urllib3.connectionpool:connectionpool.py:868 Retrying (Retry(total=2, connect=None, read=None, redirect=None, status=None)) after connection broken by 'NewConnectionError('<urllib3.connection.HTTPConnection object at 0x10530cad0>: Failed to establish a new connection: [Errno 61] Connection refused')': /status
WARNING  urllib3.connectionpool:connectionpool.py:868 Retrying (Retry(total=1, connect=None, read=None, redirect=None, status=None)) after connection broken by 'NewConnectionError('<urllib3.connection.HTTPConnection object at 0x105242350>: Failed to establish a new connection: [Errno 61] Connection refused')': /status
WARNING  urllib3.connectionpool:connectionpool.py:868 Retrying (Retry(total=0, connect=None, read=None, redirect=None, status=None)) after connection broken by 'NewConnectionError('<urllib3.connection.HTTPConnection object at 0x105242710>: Failed to establish a new connection: [Errno 61] Connection refused')': /status
WARNING  urllib3.connectionpool:connectionpool.py:868 Retrying (Retry(total=2, connect=None, read=None, redirect=None, status=None)) after connection broken by 'NewConnectionError('<urllib3.connection.HTTPConnection object at 0x1051b7490>: Failed to establish a new connection: [Errno 61] Connection refused')': /status
WARNING  urllib3.connectionpool:connectionpool.py:868 Retrying (Retry(total=1, connect=None, read=None, redirect=None, status=None)) after connection broken by 'NewConnectionError('<urllib3.connection.HTTPConnection object at 0x1052f9130>: Failed to establish a new connection: [Errno 61] Connection refused')': /status
WARNING  urllib3.connectionpool:connectionpool.py:868 Retrying (Retry(total=0, connect=None, read=None, redirect=None, status=None)) after connection broken by 'NewConnectionError('<urllib3.connection.HTTPConnection object at 0x105308c00>: Failed to establish a new connection: [Errno 61] Connection refused')': /status
WARNING  urllib3.connectionpool:connectionpool.py:868 Retrying (Retry(total=2, connect=None, read=None, redirect=None, status=None)) after connection broken by 'NewConnectionError('<urllib3.connection.HTTPConnection object at 0x105309370>: Failed to establish a new connection: [Errno 61] Connection refused')': /status
WARNING  urllib3.connectionpool:connectionpool.py:868 Retrying (Retry(total=1, connect=None, read=None, redirect=None, status=None)) after connection broken by 'NewConnectionError('<urllib3.connection.HTTPConnection object at 0x1053096a0>: Failed to establish a new connection: [Errno 61] Connection refused')': /status
WARNING  urllib3.connectionpool:connectionpool.py:868 Retrying (Retry(total=0, connect=None, read=None, redirect=None, status=None)) after connection broken by 'NewConnectionError('<urllib3.connection.HTTPConnection object at 0x1053099d0>: Failed to establish a new connection: [Errno 61] Connection refused')': /status
WARNING  urllib3.connectionpool:connectionpool.py:868 Retrying (Retry(total=2, connect=None, read=None, redirect=None, status=None)) after connection broken by 'NewConnectionError('<urllib3.connection.HTTPConnection object at 0x105309150>: Failed to establish a new connection: [Errno 61] Connection refused')': /status
WARNING  urllib3.connectionpool:connectionpool.py:868 Retrying (Retry(total=1, connect=None, read=None, redirect=None, status=None)) after connection broken by 'NewConnectionError('<urllib3.connection.HTTPConnection object at 0x105309f20>: Failed to establish a new connection: [Errno 61] Connection refused')': /status
WARNING  urllib3.connectionpool:connectionpool.py:868 Retrying (Retry(total=0, connect=None, read=None, redirect=None, status=None)) after connection broken by 'NewConnectionError('<urllib3.connection.HTTPConnection object at 0x10530a250>: Failed to establish a new connection: [Errno 61] Connection refused')': /status
WARNING  urllib3.connectionpool:connectionpool.py:868 Retrying (Retry(total=2, connect=None, read=None, redirect=None, status=None)) after connection broken by 'NewConnectionError('<urllib3.connection.HTTPConnection object at 0x10530a8b0>: Failed to establish a new connection: [Errno 61] Connection refused')': /status
WARNING  urllib3.connectionpool:connectionpool.py:868 Retrying (Retry(total=1, connect=None, read=None, redirect=None, status=None)) after connection broken by 'NewConnectionError('<urllib3.connection.HTTPConnection object at 0x10530abe0>: Failed to establish a new connection: [Errno 61] Connection refused')': /status
WARNING  urllib3.connectionpool:connectionpool.py:868 Retrying (Retry(total=0, connect=None, read=None, redirect=None, status=None)) after connection broken by 'NewConnectionError('<urllib3.connection.HTTPConnection object at 0x10530af10>: Failed to establish a new connection: [Errno 61] Connection refused')': /status
WARNING  urllib3.connectionpool:connectionpool.py:868 Retrying (Retry(total=2, connect=None, read=None, redirect=None, status=None)) after connection broken by 'NewConnectionError('<urllib3.connection.HTTPConnection object at 0x10530b570>: Failed to establish a new connection: [Errno 61] Connection refused')': /status
WARNING  urllib3.connectionpool:connectionpool.py:868 Retrying (Retry(total=1, connect=None, read=None, redirect=None, status=None)) after connection broken by 'NewConnectionError('<urllib3.connection.HTTPConnection object at 0x10530b8a0>: Failed to establish a new connection: [Errno 61] Connection refused')': /status
WARNING  urllib3.connectionpool:connectionpool.py:868 Retrying (Retry(total=0, connect=None, read=None, redirect=None, status=None)) after connection broken by 'NewConnectionError('<urllib3.connection.HTTPConnection object at 0x10530bbd0>: Failed to establish a new connection: [Errno 61] Connection refused')': /status
WARNING  urllib3.connectionpool:connectionpool.py:868 Retrying (Retry(total=2, connect=None, read=None, redirect=None, status=None)) after connection broken by 'NewConnectionError('<urllib3.connection.HTTPConnection object at 0x105338270>: Failed to establish a new connection: [Errno 61] Connection refused')': /status
WARNING  urllib3.connectionpool:connectionpool.py:868 Retrying (Retry(total=1, connect=None, read=None, redirect=None, status=None)) after connection broken by 'NewConnectionError('<urllib3.connection.HTTPConnection object at 0x1053385a0>: Failed to establish a new connection: [Errno 61] Connection refused')': /status
WARNING  urllib3.connectionpool:connectionpool.py:868 Retrying (Retry(total=0, connect=None, read=None, redirect=None, status=None)) after connection broken by 'NewConnectionError('<urllib3.connection.HTTPConnection object at 0x1053388d0>: Failed to establish a new connection: [Errno 61] Connection refused')': /status
WARNING  urllib3.connectionpool:connectionpool.py:868 Retrying (Retry(total=2, connect=None, read=None, redirect=None, status=None)) after connection broken by 'NewConnectionError('<urllib3.connection.HTTPConnection object at 0x105338f30>: Failed to establish a new connection: [Errno 61] Connection refused')': /status
WARNING  urllib3.connectionpool:connectionpool.py:868 Retrying (Retry(total=1, connect=None, read=None, redirect=None, status=None)) after connection broken by 'NewConnectionError('<urllib3.connection.HTTPConnection object at 0x105339260>: Failed to establish a new connection: [Errno 61] Connection refused')': /status
WARNING  urllib3.connectionpool:connectionpool.py:868 Retrying (Retry(total=0, connect=None, read=None, redirect=None, status=None)) after connection broken by 'NewConnectionError('<urllib3.connection.HTTPConnection object at 0x105339590>: Failed to establish a new connection: [Errno 61] Connection refused')': /status
INFO     root:conftest.py:45 Running test: test_dummy
INFO     root:conftest.py:55 Test passed: test_dummy