{"uid":"4b4757e66a1912dae1a509f688f20b0f","name":"categories","children":[{"name":"Test defects","children":[{"name":"urllib3.exceptions.MaxRetryError: HTTPConnectionPool(host='localhost', port=4723): Max retries exceeded with url: /session (Caused by NewConnectionError('<urllib3.connection.HTTPConnection object at 0x103a4e780>: Failed to establish a new connection: [Errno 61] Connection refused'))","children":[{"name":"test_login","uid":"9b48cf1d93468078","parentUid":"d4f68c46af05c49fa2345e61fc20320f","status":"broken","time":{"start":1743275076385,"stop":1743275076385,"duration":0},"flaky":false,"newFailed":false,"newPassed":false,"newBroken":false,"retriesCount":1,"retriesStatusChange":false,"parameters":[],"tags":["@pytest.mark.usefixtures('setup_class')"]}],"uid":"d4f68c46af05c49fa2345e61fc20320f"}],"uid":"bdbf199525818fae7a8651db9eafe741"}]}